INFO: Starting training:
        Epochs:          5
        Batch size:      1
        Learning rate:   1e-05
        Training size:   759
        Validation size: 84
        Checkpoints:     True
        Device:          cpu
        Images scaling:  0.5
        Mixed Precision: False
Epoch 1/5:   0%|                                                                                                    | 0/759 [00:04<?, ?img/s]
Traceback (most recent call last):
  File "train.py", line 191, in <module>
    amp=args.amp)
  File "train.py", line 79, in train_net
    for batch in train_loader:
  File "D:\Python37\lib\site-packages\torch\utils\data\dataloader.py", line 530, in __next__
    data = self._next_data()
  File "D:\Python37\lib\site-packages\torch\utils\data\dataloader.py", line 1224, in _next_data
    return self._process_data(data)
  File "D:\Python37\lib\site-packages\torch\utils\data\dataloader.py", line 1250, in _process_data
    data.reraise()
  File "D:\Python37\lib\site-packages\torch\_utils.py", line 457, in reraise
    raise exception
ValueError: Caught ValueError in DataLoader worker process 0.
Original Traceback (most recent call last):
  File "D:\Python37\lib\site-packages\torch\utils\data\_utils\worker.py", line 287, in _worker_loop
    data = fetcher.fetch(index)
  File "D:\Python37\lib\site-packages\torch\utils\data\_utils\fetch.py", line 49, in fetch
    data = [self.dataset[idx] for idx in possibly_batched_index]
  File "D:\Python37\lib\site-packages\torch\utils\data\_utils\fetch.py", line 49, in <listcomp>
    data = [self.dataset[idx] for idx in possibly_batched_index]
  File "D:\Python37\lib\site-packages\torch\utils\data\dataset.py", line 471, in __getitem__
    return self.dataset[self.indices[idx]]
  File "D:\GitHub_test\Pytorch-UNet\utils\data_loading.py", line 64, in __getitem__
    mask = self.load(mask_file[0])
  File "D:\GitHub_test\Pytorch-UNet\utils\data_loading.py", line 50, in load
    return Image.fromarray(np.load(filename))
  File "D:\Python37\lib\site-packages\numpy\lib\npyio.py", line 445, in load
    raise ValueError("Cannot load file containing pickled data "
ValueError: Cannot load file containing pickled data when allow_pickle=False